<?xml version="1.0"?>
<robot xmlns:xacro="http://www.ros.org/wiki/xacro" name="marvin_dual">

  <!--
    Dual-arm composite URDF (xacro).
    - Includes both left and right arm models from `asset_description`.
    - Adds a common `world` link and fixed joints to each arm base.
    - Adds two ros2_control hardware components (left + right) via macros.

    Args:
      left_xyz, left_rpy:  mount pose of Base_L w.r.t world
      right_xyz, right_rpy: mount pose of Base_R w.r.t world
  -->

  <xacro:arg name="left_xyz" default="0 0.037 0.3618964" />
  <xacro:arg name="left_rpy" default="-1.5707963 0 0" />
  <xacro:arg name="right_xyz" default="0 -0.037 0.3618964" />
  <xacro:arg name="right_rpy" default="1.5707963 0 0" />
  <xacro:arg name="use_gripper_L" default="false" />
  <xacro:arg name="use_gripper_R" default="false" />

  <link name="world" />

  <!-- Arm models -->
  <xacro:include filename="$(find asset_description)/marvin/urdf/Marvin M6-S-L-CCS-696-V4.0 urdf.urdf" />
  <xacro:include filename="$(find asset_description)/marvin/urdf/Marvin M6-S-R-CCS-696-V4.0 urdf.urdf" />

  <!-- Mount them under world -->
  <joint name="world_to_base_l" type="fixed">
    <origin xyz="$(arg left_xyz)" rpy="$(arg left_rpy)" />
    <parent link="world" />
    <child link="Base_L" />
  </joint>

  <joint name="world_to_base_r" type="fixed">
    <origin xyz="$(arg right_xyz)" rpy="$(arg right_rpy)" />
    <parent link="world" />
    <child link="Base_R" />
  </joint>

  <!-- ros2_control description (single hardware component for both arms) -->
  <xacro:include filename="$(find ros2_control_marvin)/description/ros2_control/marvin_dual_system.ros2_control.xacro" />

  <!-- Virtual gripper joints (for joint_state_publisher_gui sliders, range 0~1) -->
  <xacro:if value="$(arg use_gripper_L)">
    <link name="gripper_L_link"/>
    <joint name="gripper_L" type="revolute">
      <origin xyz="0 0 0" rpy="0 0 0"/>
      <parent link="Link7_L"/>
      <child link="gripper_L_link"/>
      <axis xyz="0 0 1"/>
      <limit lower="0.0" upper="1.0" effort="0" velocity="1.0"/>
    </joint>
  </xacro:if>

  <xacro:if value="$(arg use_gripper_R)">
    <link name="gripper_R_link"/>
    <joint name="gripper_R" type="revolute">
      <origin xyz="0 0 0" rpy="0 0 0"/>
      <parent link="Link7_R"/>
      <child link="gripper_R_link"/>
      <axis xyz="0 0 1"/>
      <limit lower="0.0" upper="1.0" effort="0" velocity="1.0"/>
    </joint>
  </xacro:if>

  <xacro:marvin_dual_ros2_control name="marvin_dual"
    use_gripper_L="$(arg use_gripper_L)"
    use_gripper_R="$(arg use_gripper_R)" />

</robot>
